Workbook

Sheet Dashboard
A1: Dashboard — Portafolio QA (saucedemo.com)
A3: Resumen de Casos de Prueba
A4: Total de casos diseñados | B4: =COUNTIF('Casos de Prueba'!$A$2:$A$329,"TC-*") -> 40
A5: Pass | B5: =COUNTIF('Casos de Prueba'!$I$2:$I$329,"Pass") -> 31
A6: Fail | B6: =COUNTIF('Casos de Prueba'!$I$2:$I$329,"Fail") -> 8
A7: Bloqueado | B7: =COUNTIF('Casos de Prueba'!$I$2:$I$329,"Bloqueado") -> 1
A8: No ejecutado | B8: =COUNTIF('Casos de Prueba'!$I$2:$I$329,"No ejecutado") -> 0
A9: % de aprobación (Pass / (Pass+Fail)) | B9: =IFERROR(B5/(B5+B6),0) -> 0.79487179
A11: Resumen de Bugs
A12: Total de bugs registrados | B12: =COUNTA('Bitácora de Bugs'!$A$2:$A$299) -> 8
A13: Críticos | B13: =COUNTIF('Bitácora de Bugs'!$E$2:$E$299,"Crítica") -> 3
A14: Altos | B14: =COUNTIF('Bitácora de Bugs'!$E$2:$E$299,"Alta") -> 2
A15: Medios | B15: =COUNTIF('Bitácora de Bugs'!$E$2:$E$299,"Media") -> 1
A16: Bajos | B16: =COUNTIF('Bitácora de Bugs'!$E$2:$E$299,"Baja") -> 2
A17: Bugs abiertos | B17: =COUNTIF('Bitácora de Bugs'!$G$2:$G$299,"Abierto") -> 8

Sheet Instrucciones
A1: Portafolio QA — Proyecto 2 (versión Excel) — Sauce Demo
A3: Este workbook reemplaza la versión en código del proyecto 2, usando hojas de cálculo como
A4: herramienta principal de diseño y seguimiento de pruebas.
A6: ORDEN DE LAS HOJAS:
A7: 1. Requisitos — lista de requisitos funcionales del sitio bajo prueba.
A8: 2. Matriz de Trazabilidad — vincula cada requisito con sus casos de prueba (se calcula sola).
A9: 3. Casos de Prueba — el módulo de Login ya está diseñado como ejemplo de referencia.
A10: Los módulos de Inventory, Cart y Checkout están marcados pero vacíos: ahí diseñas tú los
A11: casos, siguiendo el mismo formato de columnas que ves en Login.
A12: 4. Bitácora de Bugs — vacía salvo una fila de ejemplo en gris cursiva (bórrala o reemplázala).
A13: 5. Dashboard — se actualiza solo mediante fórmulas a partir de lo que llenes en las otras hojas.
A15: QUÉ EDITAR TÚ:
... A23: Verde = Pass · Rojo = Fail · Amarillo = Bloqueado · Gris = No ejecutado

Sheet Requisitos
A1: ID | B1: Descripción | C1: Módulo relacionado
A2: REQ-01 | B2: El sistema debe permitir el login con credenciales válidas. | C2: Login
A3: REQ-02 | B3: El sistema debe bloquear a usuarios marcados como 'locked out', mostrando un mensaje específico. | C3: Login
A4: REQ-03 | B4: El sistema debe rechazar credenciales inválidas o vacías, mostrando un mensaje de error visible. | C4: Login
A5: REQ-04 | B5: El usuario debe poder ordenar el listado de productos por nombre (A-Z, Z-A) y precio (menor-mayor, mayor-menor). | C5: Inventory
A6: REQ-05 | B6: El usuario debe poder agregar y quitar productos del carrito desde el listado de inventario. | C6: Inventory
A7: REQ-06 | B7: El contador (badge) del carrito debe reflejar en todo momento la cantidad correcta de productos agregados. | C7: Inventory
A8: REQ-07 | B8: El usuario debe poder ver el detalle de un producto al hacer clic en su nombre. | C8: Inventory
A9: REQ-08 | B9: El carrito debe permitir eliminar productos y continuar hacia el checkout. | C9: Cart
A10: REQ-09 | B10: El formulario de checkout debe validar que los campos obligatorios no estén vacíos. | C10: Checkout
A11: REQ-10 | B11: El sistema debe calcular correctamente el total de la compra (subtotal + impuesto). | C11: Checkout
A12: REQ-11 | B12: El sistema debe mostrar una confirmación visible al completar la compra exitosamente. | C12: Checkout
A13: REQ-12 | B13: El usuario puede interactuar correctamente con los botones despues de realizar la compra | C13: Cart

Sheet Matriz de Trazabilidad
A1: Requisito ID | B1: Descripción | C1: # Casos de prueba asociados | D1: Estado de cobertura
A2: =Requisitos!A2 -> REQ-01 | B2: =INDEX(Requisitos!$B$2:$B$13, MATCH(A2, Requisitos!$A$2:$A$13, 0)) -> El sistema debe permitir el login con credenciales válidas. | C2: =COUNTIF('Casos de Prueba'!$C$2:$C$329, A2) -> 4 | D2: =IF(C2>0,"Cubierto","Sin cobertura") -> Cubierto
A3: =Requisitos!A3 -> REQ-02 | B3: =INDEX(Requisitos!$B$2:$B$13, MATCH(A3, Requisitos!$A$2:$A$13, 0)) -> El sistema debe bloquear a usuarios marcados como 'locked out', mostrando un mensaje específico. | C3: =COUNTIF('Casos de Prueba'!$C$2:$C$329, A3) -> 1 | D3: =IF(C3>0,"Cubierto","Sin cobertura") -> Cubierto
A4: =Requisitos!A4 -> REQ-03 | B4: =INDEX(Requisitos!$B$2:$B$13, MATCH(A4, Requisitos!$A$2:$A$13, 0)) -> El sistema debe rechazar credenciales inválidas o vacías, mostrando un mensaje de error visible. | C4: =COUNTIF('Casos de Prueba'!$C$2:$C$329, A4) -> 4 | D4: =IF(C4>0,"Cubierto","Sin cobertura") -> Cubierto
A5: =Requisitos!A5 -> REQ-04 | B5: =INDEX(Requisitos!$B$2:$B$13, MATCH(A5, Requisitos!$A$2:$A$13, 0)) -> El usuario debe poder ordenar el listado de productos por nombre (A-Z, Z-A) y precio (menor-mayor, mayor-menor). | C5: =COUNTIF('Casos de Prueba'!$C$2:$C$329, A5) -> 4 | D5: =IF(C5>0,"Cubierto","Sin cobertura") -> Cubierto
A6: =Requisitos!A6 -> REQ-05 | B6: =INDEX(Requisitos!$B$2:$B$13, MATCH(A6, Requisitos!$A$2:$A$13, 0)) -> El usuario debe poder agregar y quitar productos del carrito desde el listado de inventario. | C6: =COUNTIF('Casos de Prueba'!$C$2:$C$329, A6) -> 2 | D6: =IF(C6>0,"Cubierto","Sin cobertura") -> Cubierto
A7: =Requisitos!A7 -> REQ-06 | B7: =INDEX(Requisitos!$B$2:$B$13, MATCH(A7, Requisitos!$A$2:$A$13, 0)) -> El contador (badge) del carrito debe reflejar en todo momento la cantidad correcta de productos agregados. | C7: =COUNTIF('Casos de Prueba'!$C$2:$C$329, A7) -> 4 | D7: =IF(C7>0,"Cubierto","Sin cobertura") -> Cubierto
A8: =Requisitos!A8 -> REQ-07 | B8: =INDEX(Requisitos!$B$2:$B$13, MATCH(A8, Requisitos!$A$2:$A$13, 0)) -> El usuario debe poder ver el detalle de un producto al hacer clic en su nombre. | C8: =COUNTIF('Casos de Prueba'!$C$2:$C$329, A8) -> 4 | D8: =IF(C8>0,"Cubierto","Sin cobertura") -> Cubierto
A9: =Requisitos!A9 -> REQ-08 | B9: =INDEX(Requisitos!$B$2:$B$13, MATCH(A9, Requisitos!$A$2:$A$13, 0)) -> El carrito debe permitir eliminar productos y continuar hacia el checkout. | C9: =COUNTIF('Casos de Prueba'!$C$2:$C$329, A9) -> 4 | D9: =IF(C9>0,"Cubierto","Sin cobertura") -> Cubierto
A10: =Requisitos!A10 -> REQ-09 | B10: =INDEX(Requisitos!$B$2:$B$13, MATCH(A10, Requisitos!$A$2:$A$13, 0)) -> El formulario de checkout debe validar que los campos obligatorios no estén vacíos. | C10: =COUNTIF('Casos de Prueba'!$C$2:$C$329, A10) -> 7 | D10: =IF(C10>0,"Cubierto","Sin cobertura") -> Cubierto
A11: =Requisitos!A11 -> REQ-10 | B11: =INDEX(Requisitos!$B$2:$B$13, MATCH(A11, Requisitos!$A$2:$A$13, 0)) -> El sistema debe calcular correctamente el total de la compra (subtotal + impuesto). | C11: =COUNTIF('Casos de Prueba'!$C$2:$C$329, A11) -> 1 | D11: =IF(C11>0,"Cubierto","Sin cobertura") -> Cubierto
A12: =Requisitos!A12 -> REQ-11 | B12: =INDEX(Requisitos!$B$2:$B$13, MATCH(A12, Requisitos!$A$2:$A$13, 0)) -> El sistema debe mostrar una confirmación visible al completar la compra exitosamente. | C12: =COUNTIF('Casos de Prueba'!$C$2:$C$329, A12) -> 2 | D12: =IF(C12>0,"Cubierto","Sin cobertura") -> Cubierto
A13: =Requisitos!A13 -> REQ-12 | B13: =INDEX(Requisitos!$B$2:$B$13, MATCH(A13, Requisitos!$A$2:$A$13, 0)) -> El usuario puede interactuar correctamente con los botones despues de realizar la compra | C13: =COUNTIF('Casos de Prueba'!$C$2:$C$329, A13) -> 3 | D13: =IF(C13>0,"Cubierto","Sin cobertura") -> Cubierto

Sheet Casos de Prueba
A1: ID | B1: Módulo | C1: Requisito | D1: Técnica | E1: Precondición | F1: Pasos | G1: Resultado esperado | H1: Resultado obtenido | I1: Estado | J1: No. de Bug | K1: Prioridad | L1: Fecha de ejecución
A2: Módulo: Login
A3: TC-001 | B3: Login | C3: REQ-01 | D3: Clases de equivalencia | E3: Estar en /login | F3: 1. Ingresar 'standard_user' en usuario 2. Ingresar 'secret_sauce' en contraseña 3. Clic en Login | G3: Acceso concedido, redirección a /inventory.html | H3: Acceso concedido, redirección a /inventory.html | I3: Pass | K3: Alta | L3: 46270
A4: TC-002 | B4: Login | C4: REQ-01 | D4: Clases de equivalencia | E4: Estar en /login | F4: 1. Ingresar 'tomsmith' en usuario 2. Ingresar 'SuperSecretPassword!' en contraseña 3. Clic en Login | G4: Acceso concedido, redirección a /inventory.html | H4: Acceso negado, mensaje de alerta "Epic sadface: Username and password do not match any user in this service" | I4: Fail | J4: BUG-001 | K4: Alta | L4: 46271
A5: TC-003 | B5: Login | C5: REQ-03 | D5: Clases de equivalencia | E5: Estar en /login | F5: 1. Ingresar usuario inválido (tomsmth) 2. Ingresar contraseña válida (secret_sauce) 3. Clic en Login | G5: Acceso denegado, mensaje de error visible | H5: Acceso denegado, mensaje de error visible | I5: Pass | K5: Alta | L5: 46272
A6: TC-004 | B6: Login | C6: REQ-03 | D6: Clases de equivalencia | E6: Estar en /login | F6: 1. Ingresar usuario válido (standard_user) 2. Ingresar contraseña inválida (supersecretpassword) 3. Clic en Login | G6: Acceso denegado, mensaje de error visible | H6: Acceso denegado, mensaje de error visible | I6: Pass | K6: Alta | L6: 46273
A7: TC-005 | B7: Login | C7: REQ-03 | D7: Clases de equivalencia | E7: Estar en /login | F7: 1. Dejar ambos campos vacíos 2. Clic en Login | G7: Mensaje de validación de campos requeridos | H7: Mensaje de validación de campos requeridos | I7: Pass | K7: Media | L7: 46274
A8: TC-006 | B8: Login | C8: REQ-03 | D8: Clases de equivalencia | E8: Estar en /login | F8: 1. Dejar usuario vacío 2. Ingresar contraseña válida (secret_sauce) 3. Clic en Login | G8: Acceso denegado, mensaje de error específico | H8: Acceso denegado, mensaje de error específico | I8: Pass | K8: Media | L8: 46275
A9: TC-007 | B9: Login | C9: REQ-01 | D9: Exploratoria | E9: Estar en /login | F9: 1. Ingresar usuario con mayúsculas alteradas (StandarD_uSer) 2. Ingresar contraseña válida (secret_sauce) 3. Clic en Login | G9: Acceso denegado, mensaje de error específico | H9: Acceso denegado, mensaje de error específico | I9: Pass | K9: Baja | L9: 46276
A10: TC-008 | B10: Login | C10: REQ-02 | D10: Clases de equivalencia | E10: Estar en /login | F10: 1. Ingresar 'locked_out_user' con contraseña válida 2. Clic en Login | G10: Acceso denegado con mensaje específico de bloqueo | H10: Acceso denegado con mensaje específico de bloqueo | I10: Bloqueado | K10: Alta | L10: 46277
A11: Módulo: Inventory — diseña aquí tus casos (ordenamiento, agregar/quitar del carrito, detalle de producto). Técnica sugerida: clases de equivalencia + exploratoria.
A12: TC-009 | B12: Inventory | C12: REQ-04 | D12: Exploratoria | E12: Realizar Login Estar en /inventory | F12: 1. Hacer clic en boton del filtros 2. Seleccionar la opcoin "Name (A to Z)" | G12: Filtro aplicado, los productos se ordenan por orden alfabetico | H12: Filtro aplicado, los productos se ordenan por orden alfabetico | I12: Pass | K12: Alta | L12: 46272
A13: TC-010 | B13: Inventory | C13: REQ-04 | D13: Exploratoria | E13: Realizar Login Estar en /inventory | F13: 1. Hacer clic en boton del filtros 2. Seleccionar la opcoin "Name (Z to A)" | G13: Filtro aplicado, los productos se ordenan por orden alfabetico inverso | H13: Filtro aplicado, los productos se ordenan por orden alfabetico inverso | I13: Pass | K13: Alta | L13: 46273
A14: TC-011 | B14: Inventory | C14: REQ-04 | D14: Exploratoria | E14: Realizar Login Estar en /inventory | F14: 1. Hacer clic en boton del filtros 2. Seleccionar la opcoin "Price (low to high)" | G14: Filtro aplicado, los productos se ordenan por precio ascendente | H14: Filtro aplicado, los productos se ordenan por precio ascendente | I14: Pass | K14: Alta | L14: 46274
A15: TC-012 | B15: Inventory | C15: REQ-04 | D15: Exploratoria | E15: Realizar Login Estar en /inventory | F15: 1. Hacer clic en boton del filtros 2. Seleccionar la opcoin "Price (high to low)" | G15: Filtro aplicado, los productos se ordenan por precio descendente | H15: Filtro aplicado, los productos se ordenan por precio descendente | I15: Pass | K15: Alta | L15: 46275
A16: TC-013 | B16: Inventory | C16: REQ-07 | D16: Exploratoria | E16: Realizar Login Estar en /inventory | F16: 1. Colocar el puntero sobre nombre del producto | G16: El puntero cambia a version de vinculo, el texto cambia de color a uno más claro | H16: El puntero cambia a version de vinculo, el texto cambia de color a uno más claro | I16: Pass | K16: Baja | L16: 46276
A17: TC-014 | B17: Inventory | C17: REQ-07 | D17: Exploratoria | E17: Realizar Login Estar en /inventory | F17: 1. Colocar el puntero sobre foto del producto | G17: El puntero cambia a version de vinculo, el texto cambia de color a uno más claro | H17: El puntero cambia a version de vinculo, el texto cambia de color a uno más claro | I17: Pass | K17: Baja | L17: 46277
A18: TC-015 | B18: Inventory | C18: REQ-05 | D18: Exploratoria | E18: Realizar Login Estar en /inventory | F18: 1. Hacer clic en boton "Add to cart" en cualquier producto | G18: Producto se agrega al carrito, se muestra "1" como notificación en simbolo de carrito | H18: Producto se agrega al carrito, se muestra "1" como notificación en simbolo de carrito | I18: Pass | K18: Alta | L18: 46278
A19: TC-016 | B19: Inventory | C19: REQ-05 | D19: Exploratoria | E19: Realizar Login Estar en /inventory | F19: 1. Hacer clic en boton "Add to cart" en cualquier producto 2. Hacer clic en boton "Remove" del producto anteriormente agregado | G19: El producto agregado al carrito se elimina del mismo, la cantidad mostrada en el simbolo carrito disminuye o se elimina | H19: El producto agregado al carrito se elimina del mismo, la cantidad mostrada en el simbolo carrito disminuye o se elimina | I19: Pass | K19: Alta | L19: 46279
A20: TC-017 | B20: Inventory | C20: REQ-06 | D20: Valores límite | E20: Realizar Login Estar en /inventory | F20: 1. Hacer clic en boton "Add to cart" en todos los productos disponibles | G20: El numero de productos en el carrito debera de incrementar cada vez que se agrega un producto nuevo | H20: El numero de productos en el carrito debera de incrementar cada vez que se agrega un producto nuevo | I20: Pass | K20: Alta | L20: 46280
A21: TC-018 | B21: Inventory | C21: REQ-06 | D21: Valores límite | E21: Realizar Login Estar en /inventory | F21: 1. Hacer clic en boton "Remove" en todos los productos disponibles | G21: El numero de productos en el carrito debera de reducirse cada vez que se elimina un producto hasta desaparecer la notificación | H21: El numero de productos en el carrito debera de reducirse cada vez que se elimina un producto hasta desaparecer la notificación | I21: Pass | K21: Alta | L21: 46281
A22: TC-019 | B22: Inventory | C22: REQ-07 | D22: Exploratoria | E22: Realizar Login Estar en /inventory | F22: 1. Hacer clic en foto del producto | G22: La página cambia a /inventory-item.html?id=#, correspondiente al producto seleccionado | H22: La página cambia a /inventory-item.html?id=#, correspondiente al producto seleccionado | I22: Pass | K22: Media | L22: 46282
A23: TC-020 | B23: Inventory | C23: REQ-07 | D23: Exploratoria | E23: Realizar Login Estar en /inventory | F23: 1. Hacer clic en nombre del producto | G23: La página cambia a /inventory-item.html?id=#, correspondiente al producto seleccionado | H23: La página cambia a /inventory-item.html?id=#, correspondiente al producto seleccionado | I23: Pass | K23: Media | L23: 46283
... A25: TC-022 | B25: Inventory | C25: REQ-06 | D25: Transición de estados | E25: Realizar Login Estar en /inventory | F25: 1. Agregar algun articulo al carrito 2. Hacer clic en botón hamburgesa 3. Hacer clic en opción "Logout" 4. Iniciar sesión | G25: El carrito mantiene los productos agregados antes del cierre de sesión | H25: El carrito mantiene los productos agregados antes del cierre de sesión | I25: Pass | K25: Media | L25: 46285
A26: Módulo: Cart — diseña aquí tus casos (eliminar productos, continuar a checkout, persistencia del carrito).
A27: TC-023 | B27: Cart | C27: REQ-08 | D27: Valores límite | E27: Realizar Login Agregar algun producto al carrito | F27: 1. Hacer clic en el carrito 2. Hacer clic en botón "Remove" | G27: El producto agregado se elimina del carrito, se muestra un mensaje "No cuenta con ningun producto" | H27: El producto agregado se elimina del carrito, no se muestra ningun mensaje | I27: Fail | J27: BUG-002 | K27: Baja | L27: 46274
A28: TC-024 | B28: Cart | C28: REQ-06 | D28: Transición de estados | E28: Realizar Login Agregar algun producto al carrito | F28: 1. Hacer clic en el carrito 2. Hacer clic en botón "Continue Shoping" | G28: El producto agregado se mantiene en el carrito | H28: El producto agregado se mantiene en el carrito | I28: Pass | K28: Alta | L28: 46275
A29: TC-025 | B29: Cart | C29: REQ-08 | D29: Transición de estados | E29: Realizar Login Agregar algun producto al carrito | F29: 1. Hacer clic en el carrito 2. Hacer clic en botón "Checkout" | G29: La página cambia a /checkout-step-one.html | H29: La página cambia a /checkout-step-one.html | I29: Pass | K29: Alta | L29: 46276
A30: TC-026 | B30: Cart | C30: REQ-08 | D30: Transición de estados | E30: Realizar Login | F30: 1. Hacer clic en el carrito 2. Hacer clic en botón "Checkout" | G30: No se cambia de pagina. Mensaje "No cuentas con ningun producto en el carrito" | H30: La página cambia a /checkout-step-one.html | I30: Fail | J30: BUG-003 | K30: Alta | L30: 46277
A31: TC-027 | B31: Cart | C31: REQ-08 | D31: Exploratoria | E31: Realizar Login Contar con un carrito vacio | F31: 1. Hacer clic en el carrito | G31: No se cuenta con productos. Mensaje "Tu carrito se encuentra vacío" | H31: No se cuenta con productos. No se cuenta con ningun mensaje | I31: Fail | J31: BUG-004 | K31: Baja | L31: 46278
A32: Módulo: Checkout — diseña aquí tus casos (validación de formulario, cálculo de totales, confirmación). Técnica sugerida: tabla de decisión para combinaciones de campos vacíos.
A33: TC-028 | B33: Checkout | C33: REQ-09 | D33: Clases de equivalencia | E33: Realizar Login Agregar algun producto al carrito Estar en ventana de Checkout | F33: 1. Ingresar nombre "Juan" 2. Ingresar apellido "Lopez" 3. Ingresar zip "12345" 4. Hacer clic en botón "Continue" | G33: La pagina cambia a /checkout-step-two. Se muestra informacion del envio | H33: La pagina cambia a /checkout-step-two. Se muestra informacion del envio | I33: Pass | K33: Alta | L33: 46276
A34: TC-029 | B34: Checkout | C34: REQ-10 | D34: Valores límite | E34: Realizar Login Agregar algun producto al carrito Estar en ventana de Checkout | F34: 1. Ingresar nombre "Juan" 2. Ingresar apellido "Lopez" 3. Ingresar zip "12345" 4. Hacer clic en botón "Continue" | G34: La pagina cambia a /checkout-step-two. La cantidad sumada de los productos y el TAX es correcta | H34: La pagina cambia a /checkout-step-two. La cantidad sumada de los productos y el TAX es correcta | I34: Pass | K34: Alta | L34: 46277
A35: TC-030 | B35: Checkout | C35: REQ-09 | D35: Clases de equivalencia | E35: Realizar Login Agregar algun producto al carrito Estar en ventana de Checkout | F35: 1. Ingresar nombre "" 2. Ingresar apellido "Lopez" 3. Ingresar zip "12345" 4. Hacer clic en botón "Continue" | G35: La pagina no cambia. Mensaje de error "First Name is required" | H35: La pagina no cambia. Mensaje de error "First Name is required" | I35: Pass | K35: Media | L35: 46278
A36: TC-031 | B36: Checkout | C36: REQ-09 | D36: Clases de equivalencia | E36: Realizar Login Agregar algun producto al carrito Estar en ventana de Checkout | F36: 1. Ingresar nombre "Juan" 2. Ingresar apellido "" 3. Ingresar zip "12345" 4. Hacer clic en botón "Continue" | G36: La pagina no cambia. Mensaje de error "Last Name is required" | H36: La pagina no cambia. Mensaje de error "Last Name is required" | I36: Pass | K36: Media | L36: 46279
A37: TC-032 | B37: Checkout | C37: REQ-09 | D37: Clases de equivalencia | E37: Realizar Login Agregar algun producto al carrito Estar en ventana de Checkout | F37: 1. Ingresar nombre "Juan" 2. Ingresar apellido "Lopez" 3. Ingresar zip "" 4. Hacer clic en botón "Continue" | G37: La pagina no cambia. Mensaje de error "Postal Code is required" | H37: La pagina no cambia. Mensaje de error "Postal Code is required" | I37: Pass | K37: Media | L37: 46280
A38: TC-033 | B38: Checkout | C38: REQ-09 | D38: Clases de equivalencia | E38: Realizar Login Agregar algun producto al carrito Estar en ventana de Checkout | F38: 1. Ingresar nombre "0000" 2. Ingresar apellido "Lopez" 3. Ingresar zip "12345" 4. Hacer clic en botón "Continue" | G38: La pagina no cambia. Mensaje de error "Campo con datos no validos" | H38: La pagina cambia a /checkout-step-two. Se muestra informacion del envio | I38: Fail | J38: BUG-005 | K38: Alta | L38: 46281
A39: TC-034 | B39: Checkout | C39: REQ-09 | D39: Clases de equivalencia | E39: Realizar Login Agregar algun producto al carrito Estar en ventana de Checkout | F39: 1. Ingresar nombre "Juan" 2. Ingresar apellido "0000" 3. Ingresar zip "12345" 4. Hacer clic en botón "Continue" | G39: La pagina no cambia. Mensaje de error "Campo con datos no validos" | H39: La pagina cambia a /checkout-step-two. Se muestra informacion del envio | I39: Fail | J39: BUG-006 | K39: Alta | L39: 46282
A40: TC-035 | B40: Checkout | C40: REQ-09 | D40: Clases de equivalencia | E40: Realizar Login Agregar algun producto al carrito Estar en ventana de Checkout | F40: 1. Ingresar nombre "0000" 2. Ingresar apellido "Lopez" 3. Ingresar zip "dostrescuatro" 4. Hacer clic en botón "Continue" | G40: La pagina no cambia. Mensaje de error "Campo con datos no validos" | H40: La pagina cambia a /checkout-step-two. Se muestra informacion del envio | I40: Fail | J40: BUG-007 | K40: Alta | L40: 46283
A41: TC-036 | B41: Checkout | C41: REQ-12 | D41: Tabla de decisión | E41: Realizar Login Agregar algun producto al carrito Estar en ventana de Checkout | F41: 1. Ingresar nombre "Juan" 2. Ingresar apellido "Lopez" 3. Ingresar zip "12345" 4. Hacer clic en botón "Continue" | G41: Hacer clic en boton "Cancel" regresa al carrito | H41: Hacer clic en boton "Cancel" regresa pagina inventario | I41: Fail | J41: BUG-008 | K41: Baja | L41: 46284
...

Sheet Bitácora de Bugs
A1: ID | B1: Título | C1: Módulo | D1: Caso de prueba relacionado | E1: Severidad | F1: Prioridad | G1: Estado | H1: URL | I1: Navegador | J1: Fecha | K1: Pasos para reproducir | L1: Resultado esperado | M1: Resultado actual
A2: BUG-001 | B2: Ingreso denegado al ingresar credenciales especificas | C2: =IFERROR(INDEX('Casos de Prueba'!$B$2:$B$300, MATCH($A2,'Casos de Prueba'!$J$2:$J$300,0)), "") -> Login | D2: =IFERROR(INDEX('Casos de Prueba'!$A$2:$A$300, MATCH($A2,'Casos de Prueba'!$J$2:$J$300,0)), "") -> TC-002 | E2: Alta | F2: =IFERROR(INDEX('Casos de Prueba'!$K$2:$K$300, MATCH($A2,'Casos de Prueba'!$J$2:$J$300,0)), "") -> Alta | G2: Abierto | H2: https://www.saucedemo.com/ | I2: MS Edge | J2: =IFERROR(INDEX('Casos de Prueba'!$L$2:$L$300, MATCH($A2,'Casos de Prueba'!$J$2:$J$300,0)), "") -> 46271 | K2: =IFERROR(INDEX('Casos de Prueba'!$F$2:$F$300, MATCH($A2,'Casos de Prueba'!$J$2:$J$300,0)), "") -> 1. Ingresar 'tomsmith' en usuario 2. Ingresar 'SuperSecretPassword!' en contraseña 3. Clic en Login | L2: =IFERROR(INDEX('Casos de Prueba'!$G$2:$G$300, MATCH($A2,'Casos de Prueba'!$J$2:$J$300,0)), "") -> Acceso concedido, redirección a /inventory.html | M2: =IFERROR(IF(INDEX('Casos de Prueba'!$H$2:$H$300,MATCH($A2,'Casos de Prueba'!$J$2:$J$300,0))="","",INDEX('Casos de Prueba'!$H$2:$H$300,MATCH($A2,'Casos de Prueba'!$J$2:$J$300,0))),"") -> Acceso negado, mensaje de alerta "Epic sadface: Username and password do not match any user in this service"
A3: BUG-002 | B3: Mensaje inexistente de advertencia de carrito vacio | C3: =IFERROR(INDEX('Casos de Prueba'!$B$2:$B$300, MATCH($A3,'Casos de Prueba'!$J$2:$J$300,0)), "") -> Cart | D3: =IFERROR(INDEX('Casos de Prueba'!$A$2:$A$300, MATCH($A3,'Casos de Prueba'!$J$2:$J$300,0)), "") -> TC-023 | E3: Baja | F3: =IFERROR(INDEX('Casos de Prueba'!$K$2:$K$300, MATCH($A3,'Casos de Prueba'!$J$2:$J$300,0)), "") -> Baja | G3: Abierto | H3: https://www.saucedemo.com/cart.html | I3: MS Edge | J3: =IFERROR(INDEX('Casos de Prueba'!$L$2:$L$300, MATCH($A3,'Casos de Prueba'!$J$2:$J$300,0)), "") -> 46274 | K3: =IFERROR(INDEX('Casos de Prueba'!$F$2:$F$300, MATCH($A3,'Casos de Prueba'!$J$2:$J$300,0)), "") -> 1. Hacer clic en el carrito 2. Hacer clic en botón "Remove" | L3: =IFERROR(INDEX('Casos de Prueba'!$G$2:$G$300, MATCH($A3,'Casos de Prueba'!$J$2:$J$300,0)), "") -> El producto agregado se elimina del carrito, se muestra un mensaje "No cuenta con ningun producto" | M3: =IFERROR(IF(INDEX('Casos de Prueba'!$H$2:$H$300,MATCH($A3,'Casos de Prueba'!$J$2:$J$300,0))="","",INDEX('Casos de Prueba'!$H$2:$H$300,MATCH($A3,'Casos de Prueba'!$J$2:$J$300,0))),"") -> El producto agregado se elimina del carrito, no se muestra ningun mensaje
A4: BUG-003 | B4: Carrito permite checkout al no contar con productos | C4: =IFERROR(INDEX('Casos de Prueba'!$B$2:$B$300, MATCH($A4,'Casos de Prueba'!$J$2:$J$300,0)), "") -> Cart | D4: =IFERROR(INDEX('Casos de Prueba'!$A$2:$A$300, MATCH($A4,'Casos de Prueba'!$J$2:$J$300,0)), "") -> TC-026 | E4: Alta | F4: =IFERROR(INDEX('Casos de Prueba'!$K$2:$K$300, MATCH($A4,'Casos de Prueba'!$J$2:$J$300,0)), "") -> Alta | G4: Abierto | H4: https://www.saucedemo.com/cart.html | I4: MS Edge | J4: =IFERROR(INDEX('Casos de Prueba'!$L$2:$L$300, MATCH($A4,'Casos de Prueba'!$J$2:$J$300,0)), "") -> 46277 | K4: =IFERROR(INDEX('Casos de Prueba'!$F$2:$F$300, MATCH($A4,'Casos de Prueba'!$J$2:$J$300,0)), "") -> 1. Hacer clic en el carrito 2. Hacer clic en botón "Checkout" | L4: =IFERROR(INDEX('Casos de Prueba'!$G$2:$G$300, MATCH($A4,'Casos de Prueba'!$J$2:$J$300,0)), "") -> No se cambia de pagina. Mensaje "No cuentas con ningun producto en el carrito" | M4: =IFERROR(IF(INDEX('Casos de Prueba'!$H$2:$H$300,MATCH($A4,'Casos de Prueba'!$J$2:$J$300,0))="","",INDEX('Casos de Prueba'!$H$2:$H$300,MATCH($A4,'Casos de Prueba'!$J$2:$J$300,0))),"") -> La página cambia a /checkout-step-one.html
A5: BUG-004 | B5: Mensaje inexistente de advertencia de carrito vacio | C5: =IFERROR(INDEX('Casos de Prueba'!$B$2:$B$300, MATCH($A5,'Casos de Prueba'!$J$2:$J$300,0)), "") -> Cart | D5: =IFERROR(INDEX('Casos de Prueba'!$A$2:$A$300, MATCH($A5,'Casos de Prueba'!$J$2:$J$300,0)), "") -> TC-027 | E5: Baja | F5: =IFERROR(INDEX('Casos de Prueba'!$K$2:$K$300, MATCH($A5,'Casos de Prueba'!$J$2:$J$300,0)), "") -> Baja | G5: Abierto | H5: https://www.saucedemo.com/cart.html | I5: MS Edge | J5: =IFERROR(INDEX('Casos de Prueba'!$L$2:$L$300, MATCH($A5,'Casos de Prueba'!$J$2:$J$300,0)), "") -> 46278 | K5: =IFERROR(INDEX('Casos de Prueba'!$F$2:$F$300, MATCH($A5,'Casos de Prueba'!$J$2:$J$300,0)), "") -> 1. Hacer clic en el carrito | L5: =IFERROR(INDEX('Casos de Prueba'!$G$2:$G$300, MATCH($A5,'Casos de Prueba'!$J$2:$J$300,0)), "") -> No se cuenta con productos. Mensaje "Tu carrito se encuentra vacío" | M5: =IFERROR(IF(INDEX('Casos de Prueba'!$H$2:$H$300,MATCH($A5,'Casos de Prueba'!$J$2:$J$300,0))="","",INDEX('Casos de Prueba'!$H$2:$H$300,MATCH($A5,'Casos de Prueba'!$J$2:$J$300,0))),"") -> No se cuenta con productos. No se cuenta con ningun mensaje
A6: BUG-005 | B6: El sitio permite el checkout con datos no válidos | C6: =IFERROR(INDEX('Casos de Prueba'!$B$2:$B$300, MATCH($A6,'Casos de Prueba'!$J$2:$J$300,0)), "") -> Checkout | D6: =IFERROR(INDEX('Casos de Prueba'!$A$2:$A$300, MATCH($A6,'Casos de Prueba'!$J$2:$J$300,0)), "") -> TC-033 | E6: Crítica | F6: =IFERROR(INDEX('Casos de Prueba'!$K$2:$K$300, MATCH($A6,'Casos de Prueba'!$J$2:$J$300,0)), "") -> Alta | G6: Abierto | H6: https://www.saucedemo.com/checkout-step-one.html | I6: MS Edge | J6: =IFERROR(INDEX('Casos de Prueba'!$L$2:$L$300, MATCH($A6,'Casos de Prueba'!$J$2:$J$300,0)), "") -> 46281 | K6: =IFERROR(INDEX('Casos de Prueba'!$F$2:$F$300, MATCH($A6,'Casos de Prueba'!$J$2:$J$300,0)), "") -> 1. Ingresar nombre "0000" 2. Ingresar apellido "Lopez" 3. Ingresar zip "12345" 4. Hacer clic en botón "Continue" | L6: =IFERROR(INDEX('Casos de Prueba'!$G$2:$G$300, MATCH($A6,'Casos de Prueba'!$J$2:$J$300,0)), "") -> La pagina no cambia. Mensaje de error "Campo con datos no validos" | M6: =IFERROR(IF(INDEX('Casos de Prueba'!$H$2:$H$300,MATCH($A6,'Casos de Prueba'!$J$2:$J$300,0))="","",INDEX('Casos de Prueba'!$H$2:$H$300,MATCH($A6,'Casos de Prueba'!$J$2:$J$300,0))),"") -> La pagina cambia a /checkout-step-two. Se muestra informacion del envio
A7: BUG-006 | B7: El sitio permite el checkout con datos no válidos | C7: =IFERROR(INDEX('Casos de Prueba'!$B$2:$B$300, MATCH($A7,'Casos de Prueba'!$J$2:$J$300,0)), "") -> Checkout | D7: =IFERROR(INDEX('Casos de Prueba'!$A$2:$A$300, MATCH($A7,'Casos de Prueba'!$J$2:$J$300,0)), "") -> TC-034 | E7: Crítica | F7: =IFERROR(INDEX('Casos de Prueba'!$K$2:$K$300, MATCH($A7,'Casos de Prueba'!$J$2:$J$300,0)), "") -> Alta | G7: Abierto | H7: https://www.saucedemo.com/checkout-step-one.html | I7: MS Edge | J7: =IFERROR(INDEX('Casos de Prueba'!$L$2:$L$300, MATCH($A7,'Casos de Prueba'!$J$2:$J$300,0)), "") -> 46282 | K7: =IFERROR(INDEX('Casos de Prueba'!$F$2:$F$300, MATCH($A7,'Casos de Prueba'!$J$2:$J$300,0)), "") -> 1. Ingresar nombre "Juan" 2. Ingresar apellido "0000" 3. Ingresar zip "12345" 4. Hacer clic en botón "Continue" | L7: =IFERROR(INDEX('Casos de Prueba'!$G$2:$G$300, MATCH($A7,'Casos de Prueba'!$J$2:$J$300,0)), "") -> La pagina no cambia. Mensaje de error "Campo con datos no validos" | M7: =IFERROR(IF(INDEX('Casos de Prueba'!$H$2:$H$300,MATCH($A7,'Casos de Prueba'!$J$2:$J$300,0))="","",INDEX('Casos de Prueba'!$H$2:$H$300,MATCH($A7,'Casos de Prueba'!$J$2:$J$300,0))),"") -> La pagina cambia a /checkout-step-two. Se muestra informacion del envio
A8: BUG-007 | B8: El sitio permite el checkout con datos no válidos | C8: =IFERROR(INDEX('Casos de Prueba'!$B$2:$B$300, MATCH($A8,'Casos de Prueba'!$J$2:$J$300,0)), "") -> Checkout | D8: =IFERROR(INDEX('Casos de Prueba'!$A$2:$A$300, MATCH($A8,'Casos de Prueba'!$J$2:$J$300,0)), "") -> TC-035 | E8: Crítica | F8: =IFERROR(INDEX('Casos de Prueba'!$K$2:$K$300, MATCH($A8,'Casos de Prueba'!$J$2:$J$300,0)), "") -> Alta | G8: Abierto | H8: https://www.saucedemo.com/checkout-step-one.html | I8: MS Edge | J8: =IFERROR(INDEX('Casos de Prueba'!$L$2:$L$300, MATCH($A8,'Casos de Prueba'!$J$2:$J$300,0)), "") -> 46283 | K8: =IFERROR(INDEX('Casos de Prueba'!$F$2:$F$300, MATCH($A8,'Casos de Prueba'!$J$2:$J$300,0)), "") -> 1. Ingresar nombre "0000" 2. Ingresar apellido "Lopez" 3. Ingresar zip "dostrescuatro" 4. Hacer clic en botón "Continue" | L8: =IFERROR(INDEX('Casos de Prueba'!$G$2:$G$300, MATCH($A8,'Casos de Prueba'!$J$2:$J$300,0)), "") -> La pagina no cambia. Mensaje de error "Campo con datos no validos" | M8: =IFERROR(IF(INDEX('Casos de Prueba'!$H$2:$H$300,MATCH($A8,'Casos de Prueba'!$J$2:$J$300,0))="","",INDEX('Casos de Prueba'!$H$2:$H$300,MATCH($A8,'Casos de Prueba'!$J$2:$J$300,0))),"") -> La pagina cambia a /checkout-step-two. Se muestra informacion del envio
A9: BUG-008 | B9: Botón "Cancel" en carrito redirecciona a lugar incorrecto | C9: =IFERROR(INDEX('Casos de Prueba'!$B$2:$B$300, MATCH($A9,'Casos de Prueba'!$J$2:$J$300,0)), "") -> Checkout | D9: =IFERROR(INDEX('Casos de Prueba'!$A$2:$A$300, MATCH($A9,'Casos de Prueba'!$J$2:$J$300,0)), "") -> TC-036 | E9: Media | F9: =IFERROR(INDEX('Casos de Prueba'!$K$2:$K$300, MATCH($A9,'Casos de Prueba'!$J$2:$J$300,0)), "") -> Baja | G9: Abierto | H9: https://www.saucedemo.com/checkout-step-one.html | I9: MS Edge | J9: =IFERROR(INDEX('Casos de Prueba'!$L$2:$L$300, MATCH($A9,'Casos de Prueba'!$J$2:$J$300,0)), "") -> 46284 | K9: =IFERROR(INDEX('Casos de Prueba'!$F$2:$F$300, MATCH($A9,'Casos de Prueba'!$J$2:$J$300,0)), "") -> 1. Ingresar nombre "Juan" 2. Ingresar apellido "Lopez" 3. Ingresar zip "12345" 4. Hacer clic en botón "Continue" | L9: =IFERROR(INDEX('Casos de Prueba'!$G$2:$G$300, MATCH($A9,'Casos de Prueba'!$J$2:$J$300,0)), "") -> Hacer clic en boton "Cancel" regresa al carrito | M9: =IFERROR(IF(INDEX('Casos de Prueba'!$H$2:$H$300,MATCH($A9,'Casos de Prueba'!$J$2:$J$300,0))="","",INDEX('Casos de Prueba'!$H$2:$H$300,MATCH($A9,'Casos de Prueba'!$J$2:$J$300,0))),"") -> Hacer clic en boton "Cancel" regresa pagina inventario
